Workbook

Sheet Comparación
A2: PI: dos cronogramas desde el 5 de octubre de 2026
A4: Indicador | B4: Propuesta A | C4: Propuesta B
A5: Fecha de inicio | B5: 46300 | C5: 46300
A6: Cierre técnico | B6: 46357 | C6: 46418
A7: Integrantes previstos | B7: 1 | C7: 2
A8: Horas totales incl. reserva | B8: ='Gantt A'!B4 -> 274 | C8: ='Gantt B'!B4 -> 550
A9: Horas de trabajo estimadas | B9: =B8-B10 -> 248 | C9: =C8-C10 -> 492
A10: Reserva incluida (h) | B10: ='Gantt A'!E4 -> 26 | C10: ='Gantt B'!E4 -> 58
A11: Pico semanal proyecto (h) | B11: =MAX('Gantt A'!H8:P8) -> 38 | C11: =MAX('Gantt B'!H8:X8) -> 36
A12: Promedio por semana completa* | B12: =SUM('Gantt A'!H8:O8)/8 -> 33.25 | C12: =C8/17 -> 32.352941
A13: Pico si se realiza sola (h) | B13: =B11 -> 38 | C13: =C11 -> 36
A14: Pico promedio por integrante | B14: =B11/B7 -> 38 | C14: =C11/C7 -> 18
A15: Pico por responsable asignado | B15: =B11 -> 38 | C15: =MAX('Gantt B'!H33:X34) -> 33
A16: Supuestos y criterios de planificación
A17: Semana inicial | B17: 05–11/10: destinada a especificación. Se presupuestan 20 h de diseño; reemplazarlas por las reales cuando las tengas.
A18: Último bloque A | B18: 30/11–01/12: sólo dos días, 8 h incluyendo 4 h de reserva. El trabajo sustancial termina el 29/11.
A19: * Promedios | B19: A: primeras 8 semanas completas. B: 17 semanas completas. Las horas incluyen la contingencia.
A20: Alcance A | B20: CBV + CBNeed sobre Core, runtime explícito, listas/recursión, trazas, métricas, grafo, experimentos e informe.
A21: Alcance B | B21: A + CBN, STG (lowering y ejecución), reachability, mark-and-sweep, lifetime y visualización de memoria.
A22: Diseño común | B22: Se aprovecha la especificación amplia ya acordada. A entrega el núcleo; implementar todo B para diciembre requiere reestimar.
A23: Decisiones retomadas | B23: Sintaxis similar a Haskell; recursión mutua; stack; snapshots por transición; valores canónicos y demanda WHNF/completa.
A24: Especificación disponible | B24: Se incorporan decisiones visibles del intercambio; no se recibió un archivo consolidado de la especificación técnica.
A25: Viabilidad A | B25: Posible pero ajustada, con 32–38 h en las semanas de implementación. Congelar alcance y escribir desde octubre.
A26: Viabilidad B sola | B26: El plan suma una carga total ≤36 h/semana. Es una estimación, sin garantía: hay que verificarla con velocidad real del primer mes.
A27: Reparto B | B27: I1: lenguaje/evaluadores/STG. I2: métricas/memoria/UI. Ambos: contratos/tests/experimentos/informe.
A28: Horas por integrante | B28: El promedio divide el total por 2. B también calcula carga de I1/I2 según responsables y reparte Ambos en partes iguales; hay semanas desiguales.
... A37: Base de estimación | B37: Estimación nueva por actividad, no medición histórica. Revisar el 25/10 con parser, runtime y CBV implementados.

Sheet Gantt A
A2: Gantt A — cierre 2026-12-01
A4: Horas proyecto | B4: =SUM(G13:G26) -> 274 | D4: Reserva (h) | E4: =G26 -> 26
A5: Semanas con reserva incluida; cifras estimadas, no horas efectivamente registradas.
A6: Inicio semana | H6: 46300 | I6: 46307 | J6: 46314 | K6: 46321 | L6: 46328 | M6: 46335 | N6: 46342 | O6: 46349 | P6: 46356
A7: Fin semana | H7: 46306 | I7: 46313 | J7: 46320 | K7: 46327 | L7: 46334 | M7: 46341 | N7: 46348 | O7: 46355 | P7: 46357
A8: Carga total (h) | H8: =SUM(H13:H26) -> 20 | I8: =SUM(I13:I26) -> 32 | J8: =SUM(J13:J26) -> 36 | K8: =SUM(K13:K26) -> 38 | L8: =SUM(L13:L26) -> 38 | M8: =SUM(M13:M26) -> 36 | N8: =SUM(N13:N26) -> 34 | O8: =SUM(O13:O26) -> 32 | P8: =SUM(P13:P26) -> 8
A9: Trabajo + correcciones (h) | H9: =H8-H10 -> 20 | I9: =I8-I10 -> 30 | J9: =J8-J10 -> 34 | K9: =K8-K10 -> 34 | L9: =L8-L10 -> 36 | M9: =M8-M10 -> 32 | N9: =N8-N10 -> 32 | O9: =O8-O10 -> 26 | P9: =P8-P10 -> 4
A10: Reserva (h) | H10: =H26 -> 0 | I10: =I26 -> 2 | J10: =J26 -> 2 | K10: =K26 -> 4 | L10: =L26 -> 2 | M10: =M26 -> 4 | N10: =N26 -> 2 | O10: =O26 -> 6 | P10: =P26 -> 4
A11: Carga Flor (1 integrante) | H11: =H8 -> 20 | I11: =I8 -> 32 | J11: =J8 -> 36 | K11: =K8 -> 38 | L11: =L8 -> 38 | M11: =M8 -> 36 | N11: =N8 -> 34 | O11: =O8 -> 32 | P11: =P8 -> 8
A12: ID | B12: Actividad | C12: Responsable | D12: Inicio | E12: Fin | F12: Dependencias | G12: Horas | H12: S1 | I12: S2 | J12: S3 | K12: S4 | L12: S5 | M12: S6 | N12: S7 | O12: S8 | P12: S9
A13: A01 | B13: Especificación técnica | C13: Flor | D13: 46300 | E13: 46306 | F13: — | G13: =SUM(H13:P13) -> 20 | H13: 20
A14: A02 | B14: Lexer, parser y desugaring a Core | C14: Flor | D14: 46307 | E14: 46313 | F14: A01 | G14: =SUM(H14:P14) -> 18 | I14: 18
A15: A03 | B15: Runtime común y control de ejecución | C15: Flor | D15: 46307 | E15: 46320 | F15: A01; integra A02 | G15: =SUM(H15:P15) -> 16 | I15: 8 | J15: 8
A16: A04 | B16: Evaluador CBV | C16: Flor | D16: 46314 | E16: 46320 | F16: A02, A03 | G16: =SUM(H16:P16) -> 20 | J16: 20
A17: A05 | B17: Evaluador call-by-need | C17: Flor | D17: 46321 | E17: 46327 | F17: A04 | G17: =SUM(H17:P17) -> 26 | K17: 26
A18: A06 | B18: Listas y recursión | C18: Flor | D18: 46328 | E18: 46334 | F18: A05 | G18: =SUM(H18:P18) -> 20 | L18: 20
A19: A07 | B19: Trazas y métricas comparables | C19: Flor | D19: 46328 | E19: 46341 | F19: A03; completa con A06 | G19: =SUM(H19:P19) -> 16 | L19: 10 | M19: 6
A20: A08 | B20: Visualizador y grafo de heap | C20: Flor | D20: 46335 | E20: 46348 | F20: A05, A07 | G20: =SUM(H20:P20) -> 28 | M20: 20 | N20: 8
A21: A09 | B21: Campaña experimental del modelo | C21: Flor | D21: 46342 | E21: 46355 | F21: A06, A07 | G21: =SUM(H21:P21) -> 18 | N21: 14 | O21: 4
A22: A10 | B22: Recursión: contraste C y Haskell | C22: Flor | D22: 46342 | E22: 46355 | F22: A06; protocolo con A09 | G22: =SUM(H22:P22) -> 10 | N22: 6 | O22: 4
A23: A11 | B23: Tests e integración continuos | C23: Flor | D23: 46307 | E23: 46355 | F23: Según módulo disponible | G23: =SUM(H23:P23) -> 26 | I23: 2 | J23: 4 | K23: 6 | L23: 4 | M23: 4 | N23: 2 | O23: 4
A24: A12 | B24: Informe, análisis y documentación | C24: Flor | D24: 46307 | E24: 46355 | F24: Desde A01; resultados A09/A10 | G24: =SUM(H24:P24) -> 26 | I24: 2 | J24: 2 | K24: 2 | L24: 2 | M24: 2 | N24: 2 | O24: 14
A25: A13 | B25: Revisión y entrega técnica | C25: Flor | D25: 46356 | E25: 46357 | F25: A08–A12 | G25: =SUM(H25:P25) -> 4 | P25: 4
A26: A14 | B26: Reserva para imprevistos | C26: Flor | D26: 46307 | E26: 46357 | F26: Se consume donde sea necesario | G26: =SUM(H26:P26) -> 26 | I26: 2 | J26: 2 | K26: 4 | L26: 2 | M26: 4 | N26: 2 | O26: 6 | P26: 4
A29: Criterio de cierre por actividad
A30: A01 | B30: Cerrar sintaxis, Surface/AST/Core, ExecutionState, frames, demanda y métricas. Semana imputada a diseño, no a código.
A31: A02 | B31: Source → AST → Core. Errores de sintaxis y bindings, incluidos recursivos.
A32: A03 | B32: Heap, stack, environments, closures, step/snapshot, HALTED, errores y límites de ejecución.
A33: A04 | B33: Aplicación, operaciones y condicionales; primer evaluador validado.
A34: A05 | B34: Thunks, forcing, UpdateFrame, sharing y blackholes. Resultado canónico y observación según demanda.
A35: A06 | B35: Constructores, case, recursión mutua, map/take/folds e infinitas con demanda finita.
A36: A07 | B36: Pasos operacionales vs reducciones semánticas, aplicaciones, allocations, thunks y sharedResultHits; exportación.
A37: A08 | B37: Código, estado actual, stack, heap, métricas; step/previous/run/pause/reset y replay de snapshots.
A38: A09 | B38: Argumentos no usados, sharing, listas infinitas, folds y acumulación; mismo programa/entrada/demanda.
A39: A10 | B39: Cuatro patrones: lineal, acumulador, listas y reutilización. Scripts y tamaños acotados; registrar compilador/flags.
A40: A11 | B40: Tests semánticos, límites, errores, snapshot/replay y equivalencia de resultados finitos CBV/CBNeed.
A41: A12 | B41: Escritura incremental; tablas, gráficos, discusión, límites, README y referencias.
... A43: A14 | B43: Horas libres presupuestadas para correcciones y demoras; no son funciones adicionales.

Sheet Gantt B
A2: Gantt B — cierre 2027-01-31
A4: Horas proyecto | B4: =SUM(G13:G32) -> 550 | D4: Reserva (h) | E4: =G32 -> 58
A5: Semanas con reserva incluida; cifras estimadas, no horas efectivamente registradas.
A6: Inicio semana | H6: 46300 | I6: 46307 | J6: 46314 | K6: 46321 | L6: 46328 | M6: 46335 | N6: 46342 | O6: 46349 | P6: 46356 | Q6: 46363 | R6: 46370 | S6: 46377 | T6: 46384 | U6: 46391 | V6: 46398 | W6: 46405 | X6: 46412
A7: Fin semana | H7: 46306 | I7: 46313 | J7: 46320 | K7: 46327 | L7: 46334 | M7: 46341 | N7: 46348 | O7: 46355 | P7: 46362 | Q7: 46369 | R7: 46376 | S7: 46383 | T7: 46390 | U7: 46397 | V7: 46404 | W7: 46411 | X7: 46418
A8: Carga total (h) | H8: =SUM(H13:H32) -> 20 | I8: =SUM(I13:I32) -> 32 | J8: =SUM(J13:J32) -> 34 | K8: =SUM(K13:K32) -> 36 | L8: =SUM(L13:L32) -> 36 | M8: =SUM(M13:M32) -> 36 | N8: =SUM(N13:N32) -> 36 | O8: =SUM(O13:O32) -> 36 | ... X8: =SUM(X13:X32) -> 32
A9: Trabajo + correcciones (h) | H9: =H8-H10 -> 20 | I9: =I8-I10 -> 30 | J9: =J8-J10 -> 32 | K9: =K8-K10 -> 34 | L9: =L8-L10 -> 34 | M9: =M8-M10 -> 34 | N9: =N8-N10 -> 32 | O9: =O8-O10 -> 34 | ... X9: =X8-X10 -> 26
A10: Reserva (h) | H10: =H32 -> 0 | I10: =I32 -> 2 | J10: =J32 -> 2 | K10: =K32 -> 2 | L10: =L32 -> 2 | M10: =M32 -> 2 | N10: =N32 -> 4 | O10: =O32 -> 2 | ... X10: =X32 -> 6
A11: Promedio por integrante (2) | H11: =H8/2 -> 10 | I11: =I8/2 -> 16 | J11: =J8/2 -> 17 | K11: =K8/2 -> 18 | L11: =L8/2 -> 18 | M11: =M8/2 -> 18 | N11: =N8/2 -> 18 | O11: =O8/2 -> 18 | ... X11: =X8/2 -> 16
A12: ID | B12: Actividad | C12: Responsable | D12: Inicio | E12: Fin | F12: Dependencias | G12: Horas | H12: S1 | I12: S2 | J12: S3 | K12: S4 | L12: S5 | M12: S6 | N12: S7 | O12: S8 | P12: S9 | Q12: S10 | R12: S11 | S12: S12 | T12: S13 | U12: S14 | V12: S15 | W12: S16 | X12: S17
A13: B01 | B13: Especificación técnica compartida | C13: Ambos | D13: 46300 | E13: 46306 | F13: — | G13: =SUM(H13:X13) -> 20 | H13: 20
A14: B02 | B14: Lexer, parser y Core | C14: I1 | D14: 46307 | E14: 46313 | F14: B01 | G14: =SUM(H14:X14) -> 18 | I14: 18
A15: B03 | B15: Runtime, trazas y contratos | C15: Ambos | D15: 46307 | E15: 46320 | F15: B01; integra B02 | G15: =SUM(H15:X15) -> 16 | I15: 8 | J15: 8
A16: B04 | B16: CBV | C16: I1 | D16: 46314 | E16: 46320 | F16: B02, B03 | G16: =SUM(H16:X16) -> 20 | J16: 20
A17: B05 | B17: Call-by-need | C17: I1 | D17: 46321 | E17: 46327 | F17: B04 | G17: =SUM(H17:X17) -> 26 | K17: 26
A18: B06 | B18: Listas y recursión | C18: I1 | D18: 46328 | E18: 46334 | F18: B05 | G18: =SUM(H18:X18) -> 20 | L18: 20
A19: B07 | B19: Instrumentación y métricas | C19: I2 | D19: 46328 | E19: 46341 | F19: B03; completa con B06 | G19: =SUM(H19:X19) -> 22 | L19: 10 | M19: 12
A20: B08 | B20: Visualizador base y heap graph | C20: I2 | D20: 46321 | E20: 46355 | F20: B03; integra B05/B07 | G20: =SUM(H20:X20) -> 50 | K20: 4 | M20: 18 | N20: 20 | O20: 8
A21: B09 | B21: STG: lowering y representación | C21: I1 | D21: 46342 | E21: 46355 | F21: B06; contrato B01 | G21: =SUM(H21:X21) -> 24 | N21: 8 | O21: 16
A22: B10 | B22: STG: máquina e integración | C22: I1 | D22: 46356 | E22: 46369 | F22: B09 | G22: =SUM(H22:X22) -> 30 | P22: 18 | Q22: 12
A23: B11 | B23: Call-by-name | C23: I1 | D23: 46356 | E23: 46369 | F23: B05, B07 | G23: =SUM(H23:X23) -> 14 | P23: 10 | Q23: 4
A24: B12 | B24: Reachability y mark-and-sweep | C24: I2 | D24: 46363 | E24: 46376 | F24: B03, B07; contrato roots B10 | G24: =SUM(H24:X24) -> 32 | Q24: 12 | R24: 20
A25: B13 | B25: Lifetime y visualización de memoria | C25: I2 | D25: 46370 | E25: 46383 | F25: B12 | G25: =SUM(H25:X25) -> 18 | R25: 8 | S25: 10
A26: B14 | B26: Experimentos preliminares y base | C26: Ambos | D26: 46349 | E26: 46397 | F26: B06–B08 | G26: =SUM(H26:X26) -> 24 | O26: 6 | S26: 8 | U26: 10
A27: B15 | B27: Recursión: contraste C y Haskell | C27: Ambos | D27: 46377 | E27: 46404 | F27: B06; protocolo B14 | G27: =SUM(H27:X27) -> 18 | S27: 6 | U27: 8 | V27: 4
A28: B16 | B28: Campaña definitiva y dataset | C28: Ambos | D28: 46398 | E28: 46404 | F28: B10–B15 y estabilización | G28: =SUM(H28:X28) -> 24 | V28: 24
A29: B17 | B29: Tests e integración continuos | C29: Ambos | D29: 46307 | E29: 46411 | F29: Según módulo disponible | G29: =SUM(H29:X29) -> 36 | I29: 2 | J29: 2 | K29: 2 | L29: 2 | M29: 2 | N29: 2 | O29: 2 | P29: 2 | Q29: 2 | R29: 2 | S29: 2 | T29: 6 | U29: 2 | V29: 2 | W29: 4
A30: B18 | B30: Informe y análisis incremental | C30: Ambos | D30: 46307 | E30: 46418 | F30: Desde B01; dataset B16 | G30: =SUM(H30:X30) -> 70 | I30: 2 | J30: 2 | K30: 2 | L30: 2 | M30: 2 | N30: 2 | O30: 2 | P30: 2 | Q30: 2 | R30: 2 | S30: 2 | T30: 6 | W30: 26 | X30: 16
A31: B19 | B31: Documentación, demo y entrega | C31: Ambos | D31: 46412 | E31: 46418 | F31: B16–B18 | G31: =SUM(H31:X31) -> 10 | X31: 10
A32: B20 | B32: Reserva para imprevistos | C32: Ambos | D32: 46307 | E32: 46418 | F32: Se consume donde sea necesario | G32: =SUM(H32:X32) -> 58 | I32: 2 | J32: 2 | K32: 2 | L32: 2 | M32: 2 | N32: 4 | O32: 2 | P32: 4 | Q32: 4 | R32: 4 | S32: 4 | T32: 4 | U32: 4 | V32: 6 | W32: 6 | X32: 6
A33: Carga I1 (h) | H33: =SUMIF($C$13:$C$32,"I1",H13:H32)+SUMIF($C$13:$C$32,"Ambos",H13:H32)/2 -> 10 | I33: =SUMIF($C$13:$C$32,"I1",I13:I32)+SUMIF($C$13:$C$32,"Ambos",I13:I32)/2 -> 25 | J33: =SUMIF($C$13:$C$32,"I1",J13:J32)+SUMIF($C$13:$C$32,"Ambos",J13:J32)/2 -> 27 | K33: =SUMIF($C$13:$C$32,"I1",K13:K32)+SUMIF($C$13:$C$32,"Ambos",K13:K32)/2 -> 29 | L33: =SUMIF($C$13:$C$32,"I1",L13:L32)+SUMIF($C$13:$C$32,"Ambos",L13:L32)/2 -> 23 | M33: =SUMIF($C$13:$C$32,"I1",M13:M32)+SUMIF($C$13:$C$32,"Ambos",M13:M32)/2 -> 3 | N33: =SUMIF($C$13:$C$32,"I1",N13:N32)+SUMIF($C$13:$C$32,"Ambos",N13:N32)/2 -> 12 | O33: =SUMIF($C$13:$C$32,"I1",O13:O32)+SUMIF($C$13:$C$32,"Ambos",O13:O32)/2 -> 22 | ... X33: =SUMIF($C$13:$C$32,"I1",X13:X32)+SUMIF($C$13:$C$32,"Ambos",X13:X32)/2 -> 16
A34: Carga I2 (h) | H34: =SUMIF($C$13:$C$32,"I2",H13:H32)+SUMIF($C$13:$C$32,"Ambos",H13:H32)/2 -> 10 | I34: =SUMIF($C$13:$C$32,"I2",I13:I32)+SUMIF($C$13:$C$32,"Ambos",I13:I32)/2 -> 7 | J34: =SUMIF($C$13:$C$32,"I2",J13:J32)+SUMIF($C$13:$C$32,"Ambos",J13:J32)/2 -> 7 | K34: =SUMIF($C$13:$C$32,"I2",K13:K32)+SUMIF($C$13:$C$32,"Ambos",K13:K32)/2 -> 7 | L34: =SUMIF($C$13:$C$32,"I2",L13:L32)+SUMIF($C$13:$C$32,"Ambos",L13:L32)/2 -> 13 | M34: =SUMIF($C$13:$C$32,"I2",M13:M32)+SUMIF($C$13:$C$32,"Ambos",M13:M32)/2 -> 33 | N34: =SUMIF($C$13:$C$32,"I2",N13:N32)+SUMIF($C$13:$C$32,"Ambos",N13:N32)/2 -> 24 | O34: =SUMIF($C$13:$C$32,"I2",O13:O32)+SUMIF($C$13:$C$32,"Ambos",O13:O32)/2 -> 14 | ... X34: =SUMIF($C$13:$C$32,"I2",X13:X32)+SUMIF($C$13:$C$32,"Ambos",X13:X32)/2 -> 16
A35: Criterio de cierre por actividad
A36: B01 | B36: Diseño común, incluido contrato Core/STG, lowerToStg, observe, estados, snapshots y métricas.
A37: B02 | B37: Source → AST → Core; sintaxis, desugaring, bindings y validación.
A38: B03 | B38: Heap, stack, environments, closures, ExecutionState, tracing y ejecución limitada.
A39: B04 | B39: Primer evaluador y observación canónica con modos de demanda.
A40: B05 | B40: Thunks, updates, sharing, blackholes y stack explícito.
A41: B06 | B41: Constructores, case, recursión mutua, map/take/folds e infinitas.
A42: B07 | B42: Métricas comparables, exportación y separación de reducciones y transiciones.
...
